{
 "bad": false,
 "new_version": "0.8.0",
 "new_version_attempts": {
  "0.1.69": 2,
  "0.1.70": 1,
  "0.1.71": 1,
  "0.1.72": 1,
  "0.1.73": 1,
  "0.1.74": 1,
  "0.1.75": 1,
  "0.1.76": 1,
  "0.1.77": 1,
  "0.1.78": 1,
  "0.1.79": 1,
  "0.1.80": 1,
  "0.1.81": 1,
  "0.1.82": 1,
  "0.1.83": 1,
  "0.1.84": 1,
  "0.1.85": 1,
  "0.2.10": 1,
  "0.2.12": 1,
  "0.2.13": 1,
  "0.2.3": 1,
  "0.2.4": 1,
  "0.2.5": 1,
  "0.2.6": 1,
  "0.2.7": 1,
  "0.2.8": 1,
  "0.2.9": 1,
  "0.3.0": 1,
  "0.3.1": 1,
  "0.3.10": 1,
  "0.3.12": 1,
  "0.3.2": 1,
  "0.3.3": 1,
  "0.3.4": 1,
  "0.3.5": 1,
  "0.3.6": 1,
  "0.3.7": 1,
  "0.3.8": 1,
  "0.3.9": 1,
  "0.4.0": 1,
  "0.4.1": 1,
  "0.4.10": 1,
  "0.4.11": 1,
  "0.4.2": 1,
  "0.4.3": 1,
  "0.4.4": 1,
  "0.4.5": 1,
  "0.4.6": 1,
  "0.4.7": 1,
  "0.4.9": 1,
  "0.5.0": 1,
  "0.5.1": 1,
  "0.5.2": 1,
  "0.6.0": 1,
  "0.6.21": 1,
  "0.7.6": 1,
  "0.7.7": 1
 },
 "new_version_errors": {
  "0.6.21": "bot error (<a href=\"https://github.com/regro/cf-scripts/actions/runs/9606342030\">bot CI job</a>): main:\nError running rerender-feedstock in container - error RuntimeError raised:\n'Failed to rerender.\noutput: INFO:conda_smithy.configure_feedstock:Downloading conda-forge-pinning-2024.06.20.18.47.46\nTraceback (most recent call last):\n  File \"/opt/conda/envs/cf-scripts/bin/conda-smithy\", line 10, in <module>\n    sys.exit(main())\n             ^^^^^^\n  File \"/opt/conda/envs/cf-scripts/lib/python3.11/site-packages/conda_smithy/cli.py\", line 737, in main\n    args.subcommand_func(args)\n  File \"/opt/conda/envs/cf-scripts/lib/python3.11/site-packages/conda_smithy/cli.py\", line 586, in __call__\n    self._call(args, args.temporary_directory)\n  File \"/opt/conda/envs/cf-scripts/lib/python3.11/site-packages/conda_smithy/cli.py\", line 589, in _call\n    configure_feedstock.main(\n  File \"/opt/conda/envs/cf-scripts/lib/python3.11/site-packages/conda_smithy/configure_feedstock.py\", line 2714, in main\n    exclusive_config_file, cf_pinning_ver = get_cached_cfp_file_path(\n                                            ^^^^^^^^^^^^^^^^^^^^^^^^^\n  File \"/opt/conda/envs/cf-scripts/lib/python3.11/site-packages/conda_smithy/configure_feedstock.py\", line 2535, in get_cached_cfp_file_path\n    get_cfp_file_path(smithy_cache)\n  File \"/opt/conda/envs/cf-scripts/lib/python3.11/site-packages/conda_smithy/configure_feedstock.py\", line 2476, in get_cfp_file_path\n    response.raise_for_status()\n  File \"/opt/conda/envs/cf-scripts/lib/python3.11/site-packages/requests/models.py\", line 1024, in raise_for_status\n    raise HTTPError(http_error_msg, response=self)\nrequests.exceptions.HTTPError: 503 Server Error: Service Unavailable for url: https://api.anaconda.org/download/conda-forge/conda-forge-pinning/2024.06.20.18.47.46/noarch/conda-forge-pinning-2024.06.20.18.47.46-hd8ed1ab_0.conda\n\n'",
  "0.7.6": "bot error (<a href=\"https://github.com/regro/cf-scripts/actions/runs/9981809334\">bot CI job</a>): main:\nError running rerender-feedstock in container - error RuntimeError raised:\n'Failed to rerender.\noutput: Traceback (most recent call last):\n  File \"/opt/conda/envs/cf-scripts/bin/conda-smithy\", line 10, in <module>\n    sys.exit(main())\n             ^^^^^^\n  File \"/opt/conda/envs/cf-scripts/lib/python3.11/site-packages/conda_smithy/cli.py\", line 766, in main\n    args.subcommand_func(args)\n  File \"/opt/conda/envs/cf-scripts/lib/python3.11/site-packages/conda_smithy/cli.py\", line 610, in __call__\n    self._call(args, args.temporary_directory)\n  File \"/opt/conda/envs/cf-scripts/lib/python3.11/site-packages/conda_smithy/cli.py\", line 613, in _call\n    configure_feedstock.main(\n  File \"/opt/conda/envs/cf-scripts/lib/python3.11/site-packages/conda_smithy/configure_feedstock.py\", line 2768, in main\n    exclusive_config_file, cf_pinning_ver = get_cached_cfp_file_path(\n                                            ^^^^^^^^^^^^^^^^^^^^^^^^^\n  File \"/opt/conda/envs/cf-scripts/lib/python3.11/site-packages/conda_smithy/configure_feedstock.py\", line 2582, in get_cached_cfp_file_path\n    current_pinning_version = get_most_recent_version(\n                              ^^^^^^^^^^^^^^^^^^^^^^^^\n  File \"/opt/conda/envs/cf-scripts/lib/python3.11/site-packages/conda_smithy/configure_feedstock.py\", line 2452, in get_most_recent_version\n    request.raise_for_status()\n  File \"/opt/conda/envs/cf-scripts/lib/python3.11/site-packages/requests/models.py\", line 1024, in raise_for_status\n    raise HTTPError(http_error_msg, response=self)\nrequests.exceptions.HTTPError: 503 Server Error: Service Unavailable for url: https://api.anaconda.org/package/conda-forge/conda-forge-pinning\n\n'",
  "0.7.7": "bot error (<a href=\"https://github.com/regro/cf-scripts/actions/runs/9984610197\">bot CI job</a>): main:\nTraceback (most recent call last):\n  File \"/home/runner/micromamba/envs/cf-scripts/lib/python3.11/site-packages/urllib3/connection.py\", line 174, in _new_conn\n    conn = connection.create_connection(\n           ^^^^^^^^^^^^^^^^^^^^^^^^^^^^^\n  File \"/home/runner/micromamba/envs/cf-scripts/lib/python3.11/site-packages/urllib3/util/connection.py\", line 95, in create_connection\n    raise err\n  File \"/home/runner/micromamba/envs/cf-scripts/lib/python3.11/site-packages/urllib3/util/connection.py\", line 85, in create_connection\n    sock.connect(sa)\nTimeoutError: timed out\n\nDuring handling of the above exception, another exception occurred:\n\nTraceback (most recent call last):\n  File \"/home/runner/micromamba/envs/cf-scripts/lib/python3.11/site-packages/urllib3/connectionpool.py\", line 715, in urlopen\n    httplib_response = self._make_request(\n                       ^^^^^^^^^^^^^^^^^^^\n  File \"/home/runner/micromamba/envs/cf-scripts/lib/python3.11/site-packages/urllib3/connectionpool.py\", line 404, in _make_request\n    self._validate_conn(conn)\n  File \"/home/runner/micromamba/envs/cf-scripts/lib/python3.11/site-packages/urllib3/connectionpool.py\", line 1060, in _validate_conn\n    conn.connect()\n  File \"/home/runner/micromamba/envs/cf-scripts/lib/python3.11/site-packages/urllib3/connection.py\", line 363, in connect\n    self.sock = conn = self._new_conn()\n                       ^^^^^^^^^^^^^^^^\n  File \"/home/runner/micromamba/envs/cf-scripts/lib/python3.11/site-packages/urllib3/connection.py\", line 179, in _new_conn\n    raise ConnectTimeoutError(\nurllib3.exceptions.ConnectTimeoutError: (<urllib3.connection.HTTPSConnection object at 0x7f159499fc90>, 'Connection to api.github.com timed out. (connect timeout=4)')\n\nDuring handling of the above exception, another exception occurred:\n\nTraceback (most recent call last):\n  File \"/home/runner/micromamba/envs/cf-scripts/lib/python3.11/site-packages/requests/adapters.py\", line 667, in send\n    resp = conn.urlopen(\n           ^^^^^^^^^^^^^\n  File \"/home/runner/micromamba/envs/cf-scripts/lib/python3.11/site-packages/urllib3/connectionpool.py\", line 801, in urlopen\n    retries = retries.increment(\n              ^^^^^^^^^^^^^^^^^^\n  File \"/home/runner/micromamba/envs/cf-scripts/lib/python3.11/site-packages/urllib3/util/retry.py\", line 594, in increment\n    raise MaxRetryError(_pool, url, error or ResponseError(cause))\nurllib3.exceptions.MaxRetryError: HTTPSConnectionPool(host='api.github.com', port=443): Max retries exceeded with url: /user (Caused by ConnectTimeoutError(<urllib3.connection.HTTPSConnection object at 0x7f159499fc90>, 'Connection to api.github.com timed out. (connect timeout=4)'))\n\nDuring handling of the above exception, another exception occurred:\n\nTraceback (most recent call last):\n  File \"/home/runner/micromamba/envs/cf-scripts/lib/python3.11/site-packages/github3/models.py\", line 201, in _request\n    return request_method(*args, **kwargs)\n           ^^^^^^^^^^^^^^^^^^^^^^^^^^^^^^^\n  File \"/home/runner/micromamba/envs/cf-scripts/lib/python3.11/site-packages/requests/sessions.py\", line 602, in get\n    return self.request(\"GET\", url, **kwargs)\n           ^^^^^^^^^^^^^^^^^^^^^^^^^^^^^^^^^^\n  File \"/home/runner/micromamba/envs/cf-scripts/lib/python3.11/site-packages/github3/session.py\", line 171, in request\n    response = super().request(*args, **kwargs)\n               ^^^^^^^^^^^^^^^^^^^^^^^^^^^^^^^^\n  File \"/home/runner/micromamba/envs/cf-scripts/lib/python3.11/site-packages/requests/sessions.py\", line 589, in request\n    resp = self.send(prep, **send_kwargs)\n           ^^^^^^^^^^^^^^^^^^^^^^^^^^^^^^\n  File \"/home/runner/micromamba/envs/cf-scripts/lib/python3.11/site-packages/requests/sessions.py\", line 703, in send\n    r = adapter.send(request, **kwargs)\n        ^^^^^^^^^^^^^^^^^^^^^^^^^^^^^^^\n  File \"/home/runner/micromamba/envs/cf-scripts/lib/python3.11/site-packages/requests/adapters.py\", line 688, in send\n    raise ConnectTimeout(e, request=request)\nrequests.exceptions.ConnectTimeout: HTTPSConnectionPool(host='api.github.com', port=443): Max retries exceeded with url: /user (Caused by ConnectTimeoutError(<urllib3.connection.HTTPSConnection object at 0x7f159499fc90>, 'Connection to api.github.com timed out. (connect timeout=4)'))\n\nDuring handling of the above exception, another exception occurred:\n\nTraceback (most recent call last):\n  File \"/home/runner/work/cf-scripts/cf-scripts/cf-scripts/conda_forge_tick/auto_tick.py\", line 573, in _run_migrator_on_feedstock_branch\n    migrator_uid, pr_json = run(\n                            ^^^^\n  File \"/home/runner/work/cf-scripts/cf-scripts/cf-scripts/conda_forge_tick/auto_tick.py\", line 197, in run\n    feedstock_dir, repo = get_repo(\n                          ^^^^^^^^^\n  File \"/home/runner/work/cf-scripts/cf-scripts/cf-scripts/conda_forge_tick/git_utils.py\", line 311, in get_repo\n    gh_username = gh.me().login\n                  ^^^^^^^\n  File \"/home/runner/micromamba/envs/cf-scripts/lib/python3.11/site-packages/github3/decorators.py\", line 24, in auth_wrapper\n    return func(self, *args, **kwargs)\n           ^^^^^^^^^^^^^^^^^^^^^^^^^^^\n  File \"/home/runner/micromamba/envs/cf-scripts/lib/python3.11/site-packages/github3/github.py\", line 1590, in me\n    json = self._json(self._get(url), 200)\n                      ^^^^^^^^^^^^^^\n  File \"/home/runner/micromamba/envs/cf-scripts/lib/python3.11/site-packages/github3/models.py\", line 216, in _get\n    return self._request(\"get\", url, **kwargs)\n           ^^^^^^^^^^^^^^^^^^^^^^^^^^^^^^^^^^^\n  File \"/home/runner/micromamba/envs/cf-scripts/lib/python3.11/site-packages/github3/models.py\", line 206, in _request\n    raise exceptions.ConnectionError(exc)\ngithub3.exceptions.ConnectionError: <class 'requests.exceptions.ConnectTimeout'>: A connection-level exception occurred: HTTPSConnectionPool(host='api.github.com', port=443): Max retries exceeded with url: /user (Caused by ConnectTimeoutError(<urllib3.connection.HTTPSConnection object at 0x7f159499fc90>, 'Connection to api.github.com timed out. (connect timeout=4)'))\n"
 }
}