{
 "PRed": [
  {
   "data": {
    "bot_rerun": false,
    "migrator_name": "CompilerRebuild",
    "migrator_version": 1,
    "name": "Python 3.7, GCC 7, R 3.5.1, openBLAS 0.3.2"
   },
   "keys": [
    "bot_rerun",
    "migrator_name",
    "migrator_version",
    "name"
   ]
  },
  {
   "PR": {
    "id": "2238e1cf-1002-4283-9761-dbca872310f6",
    "merged_at": "never issued",
    "state": "closed"
   },
   "data": {
    "bot_rerun": false,
    "migrator_name": "MigrationYaml",
    "migrator_object_version": 1,
    "migrator_version": 0,
    "name": "python38"
   },
   "keys": [
    "bot_rerun",
    "migrator_name",
    "migrator_object_version",
    "migrator_version",
    "name"
   ]
  },
  {
   "PR": {
    "number": 2,
    "state": "closed"
   },
   "data": {
    "bot_rerun": 1597087696.5071893,
    "migrator_name": "MatplotlibBase",
    "migrator_version": 0,
    "name": "matplotlib-to-matplotlib-base"
   },
   "keys": [
    "bot_rerun",
    "migrator_name",
    "migrator_version",
    "name"
   ]
  },
  {
   "PR": {
    "__lazy_json__": "pr_json/465757266.json"
   },
   "data": {
    "bot_rerun": false,
    "migrator_name": "MatplotlibBase",
    "migrator_version": 0,
    "name": "matplotlib-to-matplotlib-base"
   },
   "keys": [
    "bot_rerun",
    "migrator_name",
    "migrator_version",
    "name"
   ]
  },
  {
   "PR": {
    "number": 5,
    "state": "closed"
   },
   "data": {
    "bot_rerun": false,
    "migrator_name": "MigrationYaml",
    "migrator_object_version": 2,
    "migrator_version": 0,
    "name": "python39"
   },
   "keys": [
    "bot_rerun",
    "migrator_name",
    "migrator_object_version",
    "migrator_version",
    "name"
   ]
  },
  {
   "PR": {
    "__lazy_json__": "pr_json/553408002.json"
   },
   "data": {
    "bot_rerun": false,
    "migrator_name": "MigrationYaml",
    "migrator_object_version": 1,
    "migrator_version": 0,
    "name": "pypy"
   },
   "keys": [
    "bot_rerun",
    "migrator_name",
    "migrator_object_version",
    "migrator_version",
    "name"
   ]
  },
  {
   "PR": {
    "__lazy_json__": "pr_json/1877038583.json"
   },
   "data": {
    "bot_rerun": false,
    "migrator_name": "MigrationYaml",
    "migrator_object_version": 1,
    "migrator_version": 0,
    "name": "python312"
   },
   "keys": [
    "bot_rerun",
    "migrator_name",
    "migrator_object_version",
    "migrator_version",
    "name"
   ]
  }
 ],
 "bad": {
  "exception": "Error running migrate-feedstock in container - error VersionMigrationError raised:\n\"The recipe did not change in the version migration, a URL did not hash, or there is jinja2 syntax the bot cannot handle!\n\nPlease check the URLs in your recipe with version '2.16.2' to make sure they exist!\n\nWe also found the following errors:\n\n - could not hash URL template 'https://pypi.io/packages/source/{{ name[0] }}/{{ name }}/{{ name }}-{{ version }}.tar.bz2'\n\"",
  "traceback": [
   "Traceback (most recent call last):",
   "  File \"/home/runner/work/cf-scripts/cf-scripts/cf-scripts/conda_forge_tick/auto_tick.py\", line 567, in _run_migrator_on_feedstock_branch",
   "    migrator_uid, pr_json = run(",
   "                            ^^^^",
   "  File \"/home/runner/work/cf-scripts/cf-scripts/cf-scripts/conda_forge_tick/auto_tick.py\", line 211, in run",
   "    migration_run_data = run_migration(",
   "                         ^^^^^^^^^^^^^^",
   "  File \"/home/runner/work/cf-scripts/cf-scripts/cf-scripts/conda_forge_tick/migration_runner.py\", line 63, in run_migration",
   "    return run_migration_containerized(",
   "           ^^^^^^^^^^^^^^^^^^^^^^^^^^^^",
   "  File \"/home/runner/work/cf-scripts/cf-scripts/cf-scripts/conda_forge_tick/migration_runner.py\", line 157, in run_migration_containerized",
   "    data = run_container_task(",
   "           ^^^^^^^^^^^^^^^^^^^",
   "  File \"/home/runner/work/cf-scripts/cf-scripts/cf-scripts/conda_forge_tick/utils.py\", line 286, in run_container_task",
   "    raise ContainerRuntimeError(",
   "conda_forge_tick.utils.ContainerRuntimeError: Error running migrate-feedstock in container - error VersionMigrationError raised:",
   "\"The recipe did not change in the version migration, a URL did not hash, or there is jinja2 syntax the bot cannot handle!",
   "",
   "Please check the URLs in your recipe with version '2.16.2' to make sure they exist!",
   "",
   "We also found the following errors:",
   "",
   " - could not hash URL template 'https://pypi.io/packages/source/{{ name[0] }}/{{ name }}/{{ name }}-{{ version }}.tar.bz2'",
   "\"",
   ""
  ]
 },
 "pinning_version": "2024.05.18.00.22.24",
 "pre_pr_migrator_attempts": {
  "python310": 1456,
  "python311": 865,
  "version": 1
 },
 "pre_pr_migrator_status": {
  "python310": "not solvable (<a href=\"https://github.com/regro/autotick-bot/actions/runs/2918752635\">bot CI job</a>): main: ['No `.ci_support/*.yaml` files found! This can happen when a rerender results in no builds for a recipe (e.g., a recipe is python 2.7 only). This attempted migration is being reported as not solvable.']",
  "python311": "not solvable (<a href=\"https://github.com/regro/cf-scripts/actions/runs/6253803357\">bot CI job</a>): main: ['No `.ci_support/*.yaml` files found! This can happen when a rerender results in no builds for a recipe (e.g., a recipe is python 2.7 only). This attempted migration is being reported as not solvable.']",
  "version": "bot error: master: Traceback (most recent call last):\n  File \"/home/runner/work/autotick-bot/autotick-bot/cf-scripts/conda_forge_tick/git_utils.py\", line 135, in fetch_repo\n    _run_git_cmd(f\"git checkout --track upstream/{base_branch} {quiet}\")\n  File \"/home/runner/work/autotick-bot/autotick-bot/cf-scripts/conda_forge_tick/git_utils.py\", line 121, in _run_git_cmd\n    return subprocess.run(cmd, shell=True, check=True)\n  File \"/usr/share/miniconda/envs/run_env/lib/python3.8/subprocess.py\", line 512, in run\n    raise CalledProcessError(retcode, process.args,\nsubprocess.CalledProcessError: Command 'git checkout --track upstream/master --quiet' returned non-zero exit status 128.\n\nDuring handling of the above exception, another exception occurred:\n\nTraceback (most recent call last):\n  File \"/home/runner/work/autotick-bot/autotick-bot/cf-scripts/conda_forge_tick/auto_tick.py\", line 1018, in main\n    migrator_uid, pr_json = run(\n  File \"/home/runner/work/autotick-bot/autotick-bot/cf-scripts/conda_forge_tick/auto_tick.py\", line 163, in run\n    feedstock_dir, repo = get_repo(\n  File \"/home/runner/work/autotick-bot/autotick-bot/cf-scripts/conda_forge_tick/git_utils.py\", line 220, in get_repo\n    if fetch_repo(\n  File \"/home/runner/work/autotick-bot/autotick-bot/cf-scripts/conda_forge_tick/git_utils.py\", line 137, in fetch_repo\n    _run_git_cmd(\n  File \"/home/runner/work/autotick-bot/autotick-bot/cf-scripts/conda_forge_tick/git_utils.py\", line 121, in _run_git_cmd\n    return subprocess.run(cmd, shell=True, check=True)\n  File \"/usr/share/miniconda/envs/run_env/lib/python3.8/subprocess.py\", line 512, in run\n    raise CalledProcessError(retcode, process.args,\nsubprocess.CalledProcessError: Command 'git checkout -b master upstream/master --quiet' returned non-zero exit status 128.\n"
 },
 "smithy_version": "3.36.0"
}